Workbook
Name \A: #REF!
Name \A: #REF!
Name \A1: #REF!
Name \B: #REF!
Name \B: #REF!
Name \C: #REF!
Name \C: #REF!
Name \D: #REF!
Name \E: #REF!
Name \F: #REF!
Name \G: #REF!
Name \H: #REF!
Name \H: #REF!
Name \H: #REF!
Name \H: #REF!
Name \H: #REF!
Name \H: #REF!
Name \H: #REF!
Name \H: #REF!
Name \H: #REF!
Name \H: #REF!
Name \H: #REF!
Name \H: #REF!
Name \H: #REF!
Name \H: #REF!
Name \H: #REF!
Name \H: #REF!
Name \I: #REF!
Name \I: #REF!
Name \L: #REF!
Name \L: #REF!
Name \L: #REF!
Name \L: #REF!
Name \L: #REF!
Name \L: #REF!
Name \L: #REF!
Name \L: #REF!
Name \L: #REF!
Name \L: #REF!
Name \L: #REF!
Name \L: #REF!
Name \L: #REF!
Name \L: #REF!
Name \L: #REF!
Name \L: #REF!
Name \M: #REF!
Name \M: #REF!
Name \P: #REF!
Name \P: #REF!
Name \Y: #REF!
Name \Y: #REF!
Name \Z: #REF!
Name _____TOT58: #REF!
Name _____TOT58: #REF!
Name _____TOT58: #REF!
Name _____TOT58: #REF!
Name _____TOT58: #REF!
Name _____TOT58: #REF!
Name _____TOT58: #REF!
Name _____TOT58: #REF!

Sheet Read me
A1: Figure 7. Oil market: Global price and market developments
A2: ='7.A'!A1 -> Figure 7.A. Brent oil price and key events
A3: ='7.B'!A1 -> Figure 7.B. Tankers passing through the Strait of Hormuz
A4: ='7.C'!A1 -> Figure 7.C. Monthly increases in Brent price
A5: ='7.D'!A1 -> Figure 7.D. Oil price volatility
A7: Figure 8. Oil market: demand and supply
A8: ='8.A'!$A$1 -> Figure 8.A. Oil demand
A9: ='8.B'!A1 -> Figure 8.B. Oil exports via Strait of Hormuz, 2025
A10: ='8.C'!A1 -> Figure 8.C. Changes in oil demand by region
A11: ='8.D'!A1 -> Figure 8.D. Changes in oil supply by region
A12: ='8.E'!A1 -> Figure 8.E. Change in oil supply (in March from February 2026)
A13: ='8.F'!A1 -> Figure 8.F. Implied oil market balance
A15: Figure 9. Oil market: Outlook and risks
A16: ='9.A'!A1 -> Figure 9.A. Price forecast comparison
A17: ='9.B'!A1 -> Figure 9.B. Potential alternative sources for oil supplied via the Strait of Hormuz
A18: ='9.C'!A1 -> Figure 9.C. U.S. oil production
A19: ='9.D'!A1 -> Figure 9.D. Trade policy uncertainty
A21: Figure 10. Natural gas markets
A22: ='10.A'!A1 -> Figure 10.A. Natural gas prices
A23: ='10.B'!A1 -> Figure 10.B. Changes in natural gas consumption and production
A24: ='10.C'!A1 -> Figure 10.C. EU inventories of natural gas
A25: ='10.D'!A1 -> Figure 10.D. Natural gas forecasts
A26: ='10.E'!A1 -> Figure 10.E. Destination of LNG through Strait of Hormuz
A27: ='10.F'!A1 -> Figure 10.F. China’s LNG imports
A29: Figure 11. Coal markets
A30: ='11.A'!A1 -> Figure 11.A. Coal prices
A31: ='11.B'!A1 -> Figure 11.B. Changes in coal consumption and production
A32: ='11.C'!A1 -> Figure 11.C. Changes in U.S. coal consumption
A33: ='11.D'!A1 -> Figure 11.D. Changes in power generation by source in China and India

Sheet 7.A
A1: Figure 7.A. Brent oil price and key events
O2: Date | P2: Brent
O3: 45839 | P3: 67.4 | R3: 45951 | S3: 0
O4: 45840 | P4: 68.1 | R4: 45951 | S4: 100
O5: 45841 | P5: 69
O6: 45842 | P6: 68.6 | R6: 46024 | S6: 0 | U6: 46080 | V6: 0
O7: 45845 | P7: 68.9 | R7: 46024 | S7: 100 | U7: 46080 | V7: 100
O8: 45846 | P8: 69.9
O9: 45847 | P9: 70.2
O10: 45848 | P10: 69.4
O11: 45849 | P11: 69.5
O12: 45852 | P12: 69.8
O13: 45853 | P13: 69
O14: 45854 | P14: 68.6
O15: 45855 | P15: 69
O16: 45856 | P16: 69.4
O17: 45859 | P17: 69.2
O18: 45860 | P18: 68.9
O19: 45861 | P19: 68.6
... O34: 45882 | P34: 65.9
A35: Sources: Bloomberg; World Bank. | O35: 45883 | P35: 66.2
A36: Note: bbl = barrel; RB = República Bolivariana. Two-day moving average of Brent prices. Last observation is April 20, 2026. Vertical lines indicate major events. | O36: 45884 | P36: 66.3
O37: 45887 | P37: 66.2
O38: 45888 | P38: 66.2
A39: Return to Read Me | O39: 45889 | P39: 66.3
O40: 45890 | P40: 67.3
O41: 45891 | P41: 67.7
O42: 45894 | P42: 68.3
O43: 45895 | P43: 68
O44: 45896 | P44: 67.6
O45: 45897 | P45: 68.3
O46: 45898 | P46: 68.4
O47: 45901 | P47: 68.1
O48: 45902 | P48: 68.6
O49: 45903 | P49: 68.4
O50: 45904 | P50: 67.3
O51: 45905 | P51: 66.2
... O210: 46132 | P210: 92.9

Sheet 7.B
A1: Figure 7.B. Tankers passing through the Strait of Hormuz
Q2: Date | R2: Tanker
Q3: 46058 | R3: 58.6
Q4: 46059 | R4: 60
Q5: 46060 | R5: 59.6
Q6: 46061 | R6: 53.8
Q7: 46062 | R7: 56.4
Q8: 46063 | R8: 56.8
Q9: 46064 | R9: 58.2
Q10: 46065 | R10: 62.2
Q11: 46066 | R11: 64.4
Q12: 46067 | R12: 64.8
Q13: 46068 | R13: 64.4
Q14: 46069 | R14: 61
... Q32: 46087 | R32: 1.2
A33: Sources: Bloomberg; World Bank. | Q33: 46088 | R33: 1.4
A34: Note: Five-day moving average of vessel transits of the Strait of Hormuz. Last observation is April 20, 2026. | Q34: 46089 | R34: 1.4
Q35: 46090 | R35: 1.4
A36: Return to Read Me | Q36: 46091 | R36: 1.2
Q37: 46092 | R37: 0.8
Q38: 46093 | R38: 0.4
Q39: 46094 | R39: 0.4
Q40: 46095 | R40: 0.4
Q41: 46096 | R41: 0.6
Q42: 46097 | R42: 0.6
Q43: 46098 | R43: 0.8
Q44: 46099 | R44: 0.6
Q45: 46100 | R45: 0.6
Q46: 46101 | R46: 0.4
Q47: 46102 | R47: 0.6
Q48: 46103 | R48: 0.4
... Q77: 46132 | R77: 2.8

Sheet 7.C
A1: Figure 7.C. Monthly increases in Brent price
P3: Mar-26 | Q3: 45.9
P4: May-08 | Q4: 16.4
P5: May-09 | Q5: 14.7
P6: May-22 | Q6: 13.5
P7: Jan-22 | Q7: 13.4
P8: Sep-90 | Q8: 12.4
P9: Jun-08 | Q9: 12.1
P10: Feb-12 | Q10: 11.7
P11: Apr-15 | Q11: 11.7
P12: Oct-07 | Q12: 11.5
A36: Sources: Bloomberg; World Bank.
A37: Note: Bars show the dollar difference in the end-of-month daily price of Brent compared with the previous one. Top 10 positive changes since 1988 are plotted.
A40: Return to Read Me

Sheet 7.D
A1: Figure 7.D. Oil price volatility
Q4: Date | R4: Volatitlity
Q5: 44565 | R5: 38.6
Q6: 44566 | R6: 42
Q7: 44567 | R7: 40.7
Q8: 44568 | R8: 37
Q9: 44571 | R9: 37.4
Q10: 44572 | R10: 36
Q11: 44573 | R11: 34.4
Q12: 44574 | R12: 35.8
Q13: 44575 | R13: 39.2
Q14: 44579 | R14: 41.8
Q15: 44580 | R15: 42.6
Q16: 44581 | R16: 42
... Q34: 44607 | R34: 48.6
A35: Sources: Bloomberg; World Bank. | Q35: 44608 | R35: 48.9
A36: Note: Two-day moving average of crude oil volatility index, which measures expected 30-day volatility based on options spanning a wide range of strike prices. Daily data. Last observation is April 20, 2026. | Q36: 44609 | R36: 51.3
Q37: 44610 | R37: 52.6
Q38: 44614 | R38: 51.1
A39: Return to Read Me | Q39: 44615 | R39: 50.3
Q40: 44616 | R40: 49.8
Q41: 44617 | R41: 49.3
Q42: 44620 | R42: 51
Q43: 44621 | R43: 57
Q44: 44622 | R44: 61.5
Q45: 44623 | R45: 63
Q46: 44624 | R46: 70.9
Q47: 44627 | R47: 78.1
Q48: 44628 | R48: 77.4
Q49: 44629 | R49: 74.6
Q50: 44630 | R50: 70.3
Q51: 44631 | R51: 67.7
... Q1080: 46132 | R1080: 71.4

Sheet 8.A
A1: Figure 8.A. Oil demand
Q2: Advanced economies (RHS) | S2: EMDEs
P3: 2019Q1 | Q3: 46.7 | S3: 52.6
P4: 2019Q2 | Q4: 45.7 | S4: 53.8
P5: 2019Q3 | Q5: 46.5 | S5: 54.4
P6: 2019Q4 | Q6: 46.4 | S6: 54.4
P7: 2020Q1 | Q7: 44 | S7: 49.5
P8: 2020Q2 | Q8: 36.8 | S8: 47.8
P9: 2020Q3 | Q9: 40.9 | S9: 51.4
P10: 2020Q4 | Q10: 41.6 | S10: 52.7
P11: 2021Q1 | Q11: 41.4 | S11: 52.3
P12: 2021Q2 | Q12: 42.7 | S12: 53.1
P13: 2021Q3 | Q13: 44.1 | S13: 53.7
P14: 2021Q4 | Q14: 45.3 | S14: 54.8
... P30: 2025Q4 | Q30: 44.8 | S30: 60
P31: 2026Q1 | Q31: 44.2 | R31: 44.2 | S31: 58.6 | T31: 58.6
P32: 2026Q3 | R32: 43.4 | T32: 58
A33: Sources: International Energy Agency (IEA); World Bank. | P33: 2026Q3 | R33: 44.8 | T33: 60.1
A34: Note: EMDEs = emerging market and developing economies; mb/d = million of barrels per day; RHS = right-hand scale. Dashed lines indicate IEA forecasts for 2026Q2 to 2026Q4. | P34: 2026Q4 | R34: 44.7 | T34: 60.7
A37: Return to Read Me

Sheet 8.B
A1: Figure 8.B. Oil exports via Strait of Hormuz, 2025
J4: Strait of Hormuz | K4: Crude oil | L4: Products
J5: Americas | K5: 0.5 | L5: 0.2
J6: Africa | K6: 0.2 | L6: 0.6
J7: India | K7: 2.1 | L7: 0.7
J8: China | K8: 4.6 | L8: 0.8
J9: Other Asia | K9: 6.2 | L9: 2.1
J10: Europe | K10: 0.6 | L10: 0.5
A35: Sources: International Energy Agency (IEA); World Bank.
A36: Note: mb/d = million barrels per day. Data show oil and oil product exports transiting the Strait of Hormuz by destination. Data refer to 2025, and regional groupings follow IEA classification.
A39: Return to Read Me

Sheet 8.C
A1: Figure 8.C. Changes in oil demand by region
Q2: 2024 | R2: 2025 | S2: 2026 | T2: Demand (RHS)
P3: China | Q3: 0.46 | R3: 1.29 | S3: 0.49 | T3: 16.74
P4: EAP excl. China | Q4: 2.86 | R4: 2.64 | S4: 1.42 | T4: 5.47
P5: ECA | Q5: 1.56 | R5: 0.85 | S5: -0.11 | T5: 7.49
P6: LAC | Q6: 0.56 | R6: 1.31 | S6: 0.63 | T6: 8.59
P7: MNA | Q7: 0.51 | R7: 0.34 | S7: -2.06 | T7: 11.74
P8: SAR | Q8: 3 | R8: 1.32 | S8: 1.99 | T8: 6.19
P9: SSA | Q9: -0.03 | R9: 7.64 | S9: 3.33 | T9: 2.16
P10: AEs | Q10: 0.59 | R10: 0.05 | S10: -0.57 | T10: 44.53
A33: Sources: International Energy Agency (IEA); World Bank.
A34: Note: AEs = advanced economies; EAP = East Asia and Pacific; ECA = Europe and Central Asia; LAC = Latin America and the Caribbean; mb/d = million barrels per day; MNA = Middle East, North Africa, Afghanistan, and Pakistan; RHS = right-hand scale; SAR = South Asia; SSA = Sub-Saharan Africa. Bars show year-on-year change in demand. Diamonds show demand for 2024. Data for 2026 are IEA forecasts.
A39: Return to Read Me

Sheet 8.D
A1: Figure 8.D. Changes in oil supply by region
P2: 2023 | Q2: 2024 | R2: 2025 | S2: 2026 | T2: Supply (RHS)
O3: AEs | P3: 1.5 | Q3: 1.1 | R3: 0.9 | S3: 1 | T3: 30.1
O4: LAC | P4: 0.5 | Q4: 0.3 | R4: 0.5 | S4: 0.7 | T4: 6.5
O5: MNA | P5: 0.51 | Q5: -0.72 | R5: 1.4 | S5: -2.79 | T5: 27.79
A34: Sources: International Energy Agency (IEA); World Bank.
A35: Note: AEs = advanced economies; LAC = Latin America and the Caribbean; mb/d = million barrels per day; MNA = Middle East, North Africa, Afghanistan, and Pakistan; RHS = right-hand scale. Bars show year-on-year change in supply. Diamonds show supply for 2024.
A39: Return to Read Me

Sheet 8.E
A1: Figure 8.E. Change in oil supply (in March from February 2026)
R3: Delta (Mar - Feb)
Q4: Saudi Arabia | R4: -3.68
Q5: Iraq | R5: -3.12
Q6: Kuwait | R6: -1.53
Q7: United Arab Emirates | R7: -1.48
Q8: Qatar | R8: -1.44
Q9: Iran, Islamic Rep. | R9: -0.26
Q10: Brazil | R10: 0.1
Q11: Venezuela, RB | R11: 0.12
Q12: Russian Federation | R12: 0.29
Q13: Kazakhstan | R13: 0.48
Q14: United States | R14: 0.54
A35: Sources: International Energy Agency (IEA); World Bank.
A36: Note: mb/d = million barrels per day; RB = República Bolivariana. Data are calculated based on IEA’s Oil Market Report, April 2026 edition.
A39: Return to Read Me

Sheet 8.F
A1: Figure 8.F. Implied oil market balance
O2: Oil market balance (RHS)
O3: -1.4
N4: 2022Q2 | O4: -0.4
O5: -0.4
N6: 2022Q4 | O6: -0.2
O7: 0.8
N8: 2023Q2 | O8: -0.8
O9: -1.3
N10: 2023Q4 | O10: -0.1
O11: 0.6
N12: 2024Q2 | O12: -0.1
O13: -1.2
N14: 2024Q4 | O14: -1
O15: 0.5
N16: 2025Q2 | O16: 1.7
O17: 2.6
N18: 2025Q4 | O18: 2.6
O19: 0.1
N20: 2026Q2 | O20: -3.7
O21: 2.3
N22: 2026Q4 | O22: 2.8
A34: Sources: International Energy Agency (IEA); World Bank.
A35: Note: mb/d = million barrels per day. The implied oil market balance is the difference between supply and demand. Data are from the April 2026 IEA Oil Market Report. Data for 2026Q2 to 2026Q4 are IEA forecasts.
A38: Return to Read Me

Sheet 9.A
A1: Figure 9.A. Price forecast comparison
P3: Historical | Q3: World Bank | R3: Futures | S3: More extensive disruptions | T3: Forecast range area | U3: Consensus range | V3: Conensus range low | W3: Consensus | X3: EIA
O4: 2021 | P4: 70.4
O5: 2022 | P5: 99.8
O6: 2023 | P6: 82.6
O7: 2024 | P7: 80.7
O8: 2025 | P8: 69 | Q8: 69 | R8: 69 | S8: 69 | T8: 69 | U8: 69 | V8: 69 | W8: 69 | X8: 69
O9: 2026 | Q9: 86 | R9: 85 | S9: 115 | T9: 95 | U9: 85.6 | V9: 67.8 | W9: 75 | X9: 96
O10: 2027 | Q10: 70 | R10: 76.8 | T10: 76 | W10: 67.9 | X10: 76
A34: Sources: Bloomberg; Consensus Economics; U.S. Energy Information Administration (EIA); World Bank.
A35: Note: bbl = barrel. Futures data as of April 20, 2026. EIA data are from the April 2026 issue of Short-Term Energy Outlook. Consensus data are from the March 2026 release. Dashed lines indicate forecasts for 2026 and 2027. Futures and consensus forecasts are World Bank computations from futures and consensus data. Yellow area indicates the range for the World Bank’s forecast in case of more extensive conflict-related disruptions. Grey area indicates the 10th-90th percentile range of private-sector oil price forecasts, included in the March 2026 Consensus Forecasts release.
A42: Return to Read Me

Sheet 9.B
A1: Figure 9.B. Potential alternative sources for oil supplied via the Strait of Hormuz
J2: Oil exports through Strait of Hormuz | K2: 0 | L2: 19.9
J3: Other OPEC+ spare capacity | K3: 18.3 | L3: 1.5
J4: Additional pipelines | K4: 12.8 | L4: 5.5
J5: Inventory releases | K5: 9.5 | L5: 3.3
J6: Sanctioned oil in transit | K6: 5.6 | L6: 3.9
J7: Additional OECD supply | K7: 5.1 | L7: 0.5
J8: Global biofuels | K8: 4.6 | L8: 0.5
J9: Potential supply gap | L9: 4.6
A34: Sources: International Energy Agency (IEA); U.S. Energy Information Administration (EIA). World Bank.
A35: Notes: Data from IEA's Oil Market Report, March and April 2026 editions. To translate oil stocks into possible flows, sanctioned oil on water and IEA member countries' reserves are assumed to be released to the market over a period of four months. Figure depicts plausible alternative to oil via the Strait of Hormuz and is not a forecast.
A40: Return to Read Me

Sheet 9.C
A1: Figure 9.C. U.S. oil production
P2: Oil production
O3: 43831 | P3: 12960
O4: 43862 | P4: 13025
O5: 43891 | P5: 13025
O6: 43922 | P6: 12250
O7: 43952 | P7: 11520
O8: 43983 | P8: 10900
O9: 44013 | P9: 11040
O10: 44044 | P10: 10475
O11: 44075 | P11: 10575
O12: 44105 | P12: 10600
O13: 44136 | P13: 10875
O14: 44166 | P14: 11025
... O32: 44713 | P32: 12000
A33: Sources: U.S. Energy Information Administration (EIA); World Bank. | O33: 44743 | P33: 12040
A34: Note: mb/d = million barrels per day. Weekly data, averaged by month. Last observation is March 2026. | O34: 44774 | P34: 12100
O35: 44805 | P35: 12060
A36: Return to Read Me | O36: 44835 | P36: 11950
O37: 44866 | P37: 12100
O38: 44896 | P38: 12100
O39: 44927 | P39: 12200
O40: 44958 | P40: 12300
O41: 44986 | P41: 12220
O42: 45017 | P42: 12275
O43: 45047 | P43: 12250
O44: 45078 | P44: 12320
O45: 45108 | P45: 12250
O46: 45139 | P46: 12725
O47: 45170 | P47: 12880
O48: 45200 | P48: 13200
... O77: 46082 | P77: 13665

Sheet 9.D
A1: Figure 9.D. Trade policy uncertainty
R2: 2020-24 average
P3: 2024Q1 | Q3: 71.5 | R3: 73.3
P4: 2024Q2 | Q4: 91.5 | R4: 73.3
P5: 2024Q3 | Q5: 109.4 | R5: 73.3
P6: 2024Q4 | Q6: 256.3 | R6: 73.3
P7: 2025Q1 | Q7: 477.9 | R7: 73.3
P8: 2025Q2 | Q8: 782.3 | R8: 73.3
P9: 2025Q3 | Q9: 532 | R9: 73.3
P10: 2025Q4 | Q10: 359.1 | R10: 73.3
P11: 2026Q1 | Q11: 397.4 | R11: 73.3
A34: Sources: Caldara et al. (2019); World Bank.
A35: Note: The Global Trade Policy Uncertainty (TPU) Index, as specified in Caldara et al. (2019), tracks the frequency of trade-related news articles mentioning uncertainty across major economies, with higher values signaling greater global uncertainty. Monthly data, averaged by quarter.
A39: Return to Read Me

Sheet 10.A
A1: Figure 10.A. Natural gas prices
P3: Dates | Q3: European natural gas | R3: Asian LNG
P4: 46023 | Q4: 88.1 | R4: 91.6 | S4: 100
P5: 46024 | Q5: 90.8 | R5: 91.6 | S5: 100
P6: 46027 | Q6: 85.7 | R6: 92.9 | S6: 100
P7: 46028 | Q7: 87.8 | R7: 89.3 | S7: 100
P8: 46029 | Q8: 90 | R8: 90.1 | S8: 100
P9: 46030 | Q9: 86.7 | R9: 91.1 | S9: 100
P10: 46031 | Q10: 88.8 | R10: 89.3 | S10: 100
P11: 46034 | Q11: 94.6 | R11: 89.3 | S11: 100
P12: 46035 | Q12: 98.5 | R12: 90.7 | S12: 100
P13: 46036 | Q13: 99.5 | R13: 90.7 | S13: 100
P14: 46037 | Q14: 103.8 | R14: 90.7 | S14: 100
P15: 46038 | Q15: 115.4 | R15: 97.6 | S15: 100
... P34: 46065 | Q34: 103.2 | R34: 103.3 | S34: 100
A35: Sources: Bloomberg; World Bank. | P35: 46066 | Q35: 101.7 | R35: 103.3 | S35: 100
A36: Note: LNG = liquefied natural gas. Daily data. Last observation is April 20, 2026. | P36: 46069 | Q36: 96.7 | R36: 97 | S36: 100
P37: 46070 | Q37: 93.3 | R37: 95.7 | S37: 100
A38: Return to Read Me | P38: 46071 | Q38: 98.5 | R38: 91.7 | S38: 100
P39: 46072 | Q39: 104.9 | R39: 96.1 | S39: 100
P40: 46073 | Q40: 100.2 | R40: 100.9 | S40: 100
P41: 46076 | Q41: 99.6 | R41: 100.9 | S41: 100
P42: 46077 | Q42: 96.7 | R42: 99.3 | S42: 100
P43: 46078 | Q43: 97.2 | R43: 97.3 | S43: 100
P44: 46079 | Q44: 100.8 | R44: 98.3 | S44: 100
P45: 46080 | Q45: 100 | R45: 100 | S45: 100
P46: 46083 | Q46: 139.3 | R46: 100.9 | S46: 100
P47: 46084 | Q47: 169.9 | R47: 146.7 | S47: 100
P48: 46085 | Q48: 152.6 | R48: 190.8 | S48: 100
P49: 46086 | Q49: 158.7 | R49: 164.9 | S49: 100
P50: 46087 | Q50: 167 | R50: 173.6 | S50: 100
... P81: 46132 | Q81: 126.1 | R81: 146.4 | S81: 100

Sheet 10.B
A1: Figure 10.B. Changes in natural gas consumption and production
R2: Asia Pacific | S2: Eurasia | T2: Europe | U2: Middle East | V2: North America | W2: World | X2: RoW
P3: Consumption | Q3: 2024 | R3: 48 | S3: 25 | T3: 7 | U3: 6 | V3: 26 | W3: 116 | X3: 4
Q4: 2025 | R4: 1 | S4: -12 | T4: 15 | U4: 15 | V4: 11 | W4: 35 | X4: 5
Q5: 2026 | R5: 10 | S5: 16 | T5: -15 | U5: -13.1 | V5: 3 | W5: 0.9 | X5: 0
P6: Production | Q6: 2024 | R6: 20 | S6: 30 | T6: 3 | U6: 20 | V6: -5 | W6: 59 | X6: -9
Q7: 2025 | R7: 15 | S7: -15 | T7: -6 | U7: 15 | V7: 35 | W7: 40 | X7: -4
Q8: 2026 | R8: 15 | S8: 20 | T8: 3 | U8: -74.1 | V8: 50 | W8: 19.9 | X8: 6
A34: Sources: International Energy Agency (IEA); World Bank.
A35: Note: bcm = billion cubic meters; RoW = rest of world. Regions are defined as in the IEA’s Gas Market Report. Data for 2026 are computed by World Bank staff reflecting current geopolitical events in the Middle East and previous IEA forecasts, including those in IEA’s Oil Market Report, April 2026 edition.
A39: Return to Read Me

Sheet 10.C
A1: Figure 10.C. EU inventories of natural gas
P4: 2022 | Q4: 2023 | R4: 2024 | S4: 2025 | T4: 2026 | U4: 2017-21 average | V4: 2017-21 range | W4: Min
O6: 44927 | P6: 2046.1 | Q6: 3190.1 | R6: 3353.5 | S6: 2812 | T6: 2397.8 | U6: 2734.3 | V6: 983.4 | W6: 2403.7
O7: 44928 | P7: 2046 | Q7: 3190 | R7: 3345.1 | S7: 2793.1 | T7: 2376.7 | U7: 2717.1 | V7: 986.6 | W7: 2382.2
O8: 44929 | P8: 2040.8 | Q8: 3186.9 | R8: 3336.4 | S8: 2770.4 | T8: 2354.7 | U8: 2697.2 | V8: 998.5 | W8: 2355
O9: 44930 | P9: 2031.3 | Q9: 3184.5 | R9: 3323.3 | S9: 2748.2 | T9: 2328.8 | U9: 2676.5 | V9: 1011.5 | W9: 2327.7
O10: 44931 | P10: 2016.7 | Q10: 3179.6 | R10: 3308.7 | S10: 2730.3 | T10: 2295.5 | U10: 2655.1 | V10: 1027.9 | W10: 2296
O11: 44932 | P11: 2001.9 | Q11: 3177.7 | R11: 3294.2 | S11: 2714.6 | T11: 2262.5 | U11: 2633.5 | V11: 1040.7 | W11: 2263
O12: 44933 | P12: 1982.3 | Q12: 3176.1 | R12: 3276.6 | S12: 2695.5 | T12: 2227.5 | U12: 2610.7 | V12: 1044.5 | W12: 2237.6
O13: 44934 | P13: 1966 | Q13: 3173.4 | R13: 3245.9 | S13: 2672.3 | T13: 2192.6 | U13: 2586.8 | V13: 1049.1 | W13: 2212.6
O14: 44935 | P14: 1949.8 | Q14: 3164.8 | R14: 3213.1 | S14: 2648.6 | T14: 2163.3 | U14: 2562.1 | V14: 1058.5 | W14: 2183.8
O15: 44936 | P15: 1922 | Q15: 3155.9 | R15: 3179.4 | S15: 2624.3 | T15: 2133.6 | U15: 2537.9 | V15: 1070.5 | W15: 2155.4
O16: 44937 | P16: 1894.4 | Q16: 3147.3 | R16: 3146.7 | S16: 2600.2 | T16: 2103.5 | U16: 2514.5 | V16: 1081.3 | W16: 2128.1
O17: 44938 | P17: 1866.4 | Q17: 3139.4 | R17: 3117.4 | S17: 2575.7 | T17: 2072.8 | U17: 2493.1 | V17: 1091.7 | W17: 2101.5
... O33: 44954 | P33: 1480.2 | Q33: 2819.5 | R33: 2781.6 | S33: 2155.9 | T33: 1670 | U33: 2088.1 | V33: 1181.4 | W33: 1626.8
A34: Sources: Gas Infrastructure Europe (AGSI+); World Bank. | O34: 44955 | P34: 1466.6 | Q34: 2799.4 | R34: 2763.1 | S34: 2140.1 | T34: 1643.1 | U34: 2066.5 | V34: 1176.6 | W34: 1606.9
A35: Note: Sample includes 20 EU countries and the United Kingdom. Last observation is April 19, 2026. | O35: 44956 | P35: 1453.3 | Q35: 2777.3 | R35: 2745.1 | S35: 2120.2 | T35: 1619.1 | U35: 2044.8 | V35: 1180.7 | W35: 1584.1
O36: 44957 | P36: 1432.4 | Q36: 2764.4 | R36: 2728.2 | S36: 2098.7 | T36: 1598.8 | U36: 2022.8 | V36: 1187.6 | W36: 1560.2
A37: Return to Read Me | O37: 44958 | P37: 1415.5 | Q37: 2746.3 | R37: 2711.3 | S37: 2080.8 | T37: 1580 | U37: 2004 | V37: 1197.9 | W37: 1542.9
O38: 44959 | P38: 1398.9 | Q38: 2729 | R38: 2696.7 | S38: 2061.7 | T38: 1554.2 | U38: 1986.7 | V38: 1206.8 | W38: 1526.4
O39: 44960 | P39: 1383.2 | Q39: 2714.3 | R39: 2688.2 | S39: 2035.4 | T39: 1527.4 | U39: 1970.1 | V39: 1206.8 | W39: 1512.2
O40: 44961 | P40: 1370.3 | Q40: 2702.4 | R40: 2679.9 | S40: 2009.1 | T40: 1501 | U40: 1951.7 | V40: 1200.4 | W40: 1501.2
O41: 44962 | P41: 1361.1 | Q41: 2685.8 | R41: 2667.3 | S41: 1982.4 | T41: 1477.2 | U41: 1930.8 | V41: 1190.7 | W41: 1489.6
O42: 44963 | P42: 1352.5 | Q42: 2665.4 | R42: 2654.9 | S42: 1957.1 | T42: 1456.7 | U42: 1905.5 | V42: 1185.9 | W42: 1470
O43: 44964 | P43: 1337.5 | Q43: 2640.5 | R43: 2638.9 | S43: 1935.1 | T43: 1443.9 | U43: 1886 | V43: 1186.9 | W43: 1449.2
O44: 44965 | P44: 1323.6 | Q44: 2615.3 | R44: 2623.5 | S44: 1916 | T44: 1429.6 | U44: 1862.4 | V44: 1194.7 | W44: 1426
O45: 44966 | P45: 1310.3 | Q45: 2589.5 | R45: 2613.5 | S45: 1898.3 | T45: 1408.1 | U45: 1839.9 | V45: 1210.9 | W45: 1398.8
O46: 44967 | P46: 1294.5 | Q46: 2567.1 | R46: 2606.7 | S46: 1875.3 | T46: 1388.4 | U46: 1818.8 | V46: 1225.5 | W46: 1371.1
O47: 44968 | P47: 1278.5 | Q47: 2550.7 | R47: 2599.6 | S47: 1850 | T47: 1372 | U47: 1796.7 | V47: 1228.3 | W47: 1350.3
O48: 44969 | P48: 1265.4 | Q48: 2536.9 | R48: 2586.2 | S48: 1824 | T48: 1356.5 | U48: 1774 | V48: 1224.3 | W48: 1335.1
O49: 44970 | P49: 1255.4 | Q49: 2519.5 | R49: 2572.7 | S49: 1797.5 | T49: 1339.8 | U49: 1750.2 | V49: 1224.4 | W49: 1314.7
... O114: 45035 | P114: 1130.6 | Q114: 2192 | R114: 2396.5 | S114: 1416.2 | T114: 1177.3 | U114: 1395.4 | V114: 1490 | W114: 788.5
O115: 45036 | P115: 1140.1 | Q115: 2197.7 | R115: 2398.5 | S115: 1427.7 | U115: 1403.8 | V115: 1485.9 | W115: 803.1
O116: 45037 | P116: 1150.6 | Q116: 2205.8 | R116: 2400.5 | S116: 1438.6 | U116: 1415.1 | V116: 1480.8 | W116: 821.2
O117: 45038 | P117: 1162.8 | Q117: 2218.4 | R117: 2396.2 | S117: 1446.8 | U117: 1423.5 | V117: 1450.8 | W117: 841.5
O118: 45039 | P118: 1178.2 | Q118: 2232.1 | R118: 2390.7 | S118: 1454.4 | U118: 1438.9 | V118: 1471.1 | W118: 856.2
O119: 45040 | P119: 1194.1 | Q119: 2243 | R119: 2385.8 | S119: 1461.5 | U119: 1450.2 | V119: 1473.3 | W119: 867.7
O120: 45041 | P120: 1204.1 | Q120: 2251.6 | R120: 2381.2 | S120: 1470 | U120: 1457.6 | V120: 1475.3 | W120: 880.2
O121: 45042 | P121: 1211.9 | Q121: 2255.3 | R121: 2380 | S121: 1480.8 | U121: 1470.5 | V121: 1476.2 | W121: 892.9
O122: 45043 | P122: 1219.1 | Q122: 2262 | R122: 2385.1 | S122: 1491.3 | U122: 1479 | V122: 1475.7 | W122: 904.8
...

Sheet 10.D
A1: Figure 10.D. Natural gas forecasts
O5: 2024 | P5: 2025 | Q5: 2026f | R5: 2027f
N6: Natural gas, U.S. | O6: -12.4 | P6: 60.9 | Q6: 7.8 | R6: 5.3
N7: Natural gas, Europe | O7: -16.3 | P7: 9.1 | Q7: 25.4 | R7: -20
N8: Liquefied natural gas, Japan | O8: -10.8 | P8: -6.3 | Q8: 32.9 | R8: -18.8
A34: Source: World Bank.
A35: Note: f = forecast. Changes for 2024 and 2025 are computed from historical data while changes for 2026 and 2027 are computed from price forecasts from this publication.
A38: Return to Read Me

Sheet 10.E
A1: Figure 10.E. Destination of LNG through Strait of Hormuz
O3: 2020-21 | P3: 2022 | Q3: 2023 | R3: 2024 | S3: 1Q25
N4: China | O4: 1.2 | P4: 2.1 | Q4: 2.2 | R4: 2.5 | S4: 2.7
N5: India | O5: 1.7 | P5: 1.7 | Q5: 1.8 | R5: 1.7 | S5: 2.2
N6: TWN, KOR, PAK | O6: 2.7 | P6: 2.8 | Q6: 2.7 | R6: 2.8 | S6: 3
N7: Other Asia | O7: 2.1 | P7: 1.4 | Q7: 1.5 | R7: 1.5 | S7: 1.9
N8: Europe | O8: 2.5 | P8: 2.6 | Q8: 1.9 | R8: 1.4 | S8: 1.5
N9: RoW | O9: 0.6 | P9: 0.4 | Q9: 0.4 | R9: 0.4 | S9: 0.1
A33: Sources: U.S. Energy Information Administration (EIA); World Bank.
A34: Note: bcf/d = billion cubic feet per day; KOR = Republic of Korea; LNG = liquefied natural gas; PAK = Pakistan; RoW = rest of world; TWN = Taiwan, China. Daily volume of LNG shipped via the Strait of Hormuz for the respective time periods. In 2025Q1, the Republic of Korea; Taiwan, China; and Pakistan each accounted for about one-third of the joint share.
A39: Return to Read Me

Sheet 10.F
A1: Figure 10.F. China’s LNG imports
P2: 2023Q1 | Q2: -4.9
P3: 2023Q2 | Q3: 21.7
P4: 2023Q3 | Q4: 16
P5: 2023Q4 | Q5: 19.3
P6: 2024Q1 | Q6: 20.4
P7: 2024Q2 | Q7: 7.1
P8: 2024Q3 | Q8: 7.9
P9: 2024Q4 | Q9: -3.1
P10: 2025Q1 | Q10: -21.6
P11: 2025Q2 | Q11: -19.9
P12: 2025Q3 | Q12: -9.2
P13: 2025Q4 | Q13: 7.3
P14: 2026Q1 | Q14: -7
A34: Sources: Haver Analytics; World Bank.
A35: Note: LNG = liquefied natural gas. Monthly averages of China’s LNG imports, aggregated by quarter. Last observation is March 2026. Data show percent year-on-year change.
A38: Return to Read Me

Sheet 11.A
A1: Figure 11.A. Coal prices
T3: Coal, Australia | U3: Index
S4: 46023 | T4: 107.3 | U4: 91.8 | V4: 100
S5: 46024 | T5: 105.5 | U5: 90.2 | V5: 100
S6: 46027 | T6: 104.9 | U6: 89.7 | V6: 100
S7: 46028 | T7: 107 | U7: 91.5 | V7: 100
S8: 46029 | T8: 106.6 | U8: 91.2 | V8: 100
S9: 46030 | T9: 107.6 | U9: 92 | V9: 100
S10: 46031 | T10: 107.1 | U10: 91.6 | V10: 100
S11: 46034 | T11: 107.4 | U11: 91.9 | V11: 100
S12: 46035 | T12: 108.7 | U12: 93 | V12: 100
S13: 46036 | T13: 110 | U13: 94.1 | V13: 100
S14: 46037 | T14: 110.7 | U14: 94.7 | V14: 100
S15: 46038 | T15: 111.6 | U15: 95.5 | V15: 100
... S34: 46065 | T34: 119 | U34: 101.8 | V34: 100
A35: Sources: Bloomberg; World Bank. | S35: 46066 | T35: 119.9 | U35: 102.6 | V35: 100
A36: Note: Daily data for Australian coal prices. Last observation is April 20, 2026. | S36: 46069 | T36: 120.1 | U36: 102.7 | V36: 100
S37: 46070 | T37: 121.1 | U37: 103.6 | V37: 100
A38: Return to Read Me | S38: 46071 | T38: 122.2 | U38: 104.5 | V38: 100
S39: 46072 | T39: 121.6 | U39: 104 | V39: 100
S40: 46073 | T40: 120.5 | U40: 103.1 | V40: 100
S41: 46076 | T41: 119.4 | U41: 102.1 | V41: 100
S42: 46077 | T42: 118 | U42: 100.9 | V42: 100
S43: 46078 | T43: 117.3 | U43: 100.3 | V43: 100
S44: 46079 | T44: 117.6 | U44: 100.6 | V44: 100
S45: 46080 | T45: 116.9 | U45: 100 | V45: 100
S46: 46083 | T46: 128.7 | U46: 110.1 | V46: 100
S47: 46084 | T47: 138 | U47: 118 | V47: 100
S48: 46085 | T48: 132.9 | U48: 113.7 | V48: 100
S49: 46086 | T49: 135.3 | U49: 115.7 | V49: 100
S50: 46087 | T50: 137.3 | U50: 117.5 | V50: 100
... S81: 46132 | T81: 122.5 | U81: 104.8 | V81: 100

Sheet 11.B
A1: Figure 11.B. Changes in coal consumption and production
P2: China | Q2: India | R2: U.S. | S2: European Union | T2: RoW | U2: World
N3: Consumption | O3: 2024 | P3: 72 | Q3: 60 | R3: -12 | S3: -41 | T3: 34 | U3: 113
O4: 2025 | P4: -7 | Q4: -21 | R4: 37 | S4: -3 | T4: 22 | U4: 28
O5: 2026 | P5: 9.9 | Q5: 44.2 | R5: -18.5 | S5: -31.8 | T5: -0.8 | U5: 2.9
N6: Production | O6: 2024 | P6: 77 | Q6: 61 | R6: -68 | S6: -35 | T6: 72 | U6: 107
O7: 2025 | P7: 41 | Q7: 6 | R7: 12 | S7: 0 | T7: -67 | U7: -8
O8: 2026 | P8: 40.9 | Q8: 86.6 | R8: -4.6 | S8: -27.5 | T8: -181.8 | U8: -86.4
A33: Sources: International Energy Agency (IEA); World Bank.
A34: Note: mmt = million metric tons; RoW = rest of world. Thermal coal data are from the IEA’s Coal 2025 report. Data for 2025 are IEA estimates, and data for 2026 are computed by World Bank staff reflecting current geopolitical events in the Middle East and previous IEA forecasts.
A38: Return to Read Me

Sheet 11.C
A1: Figure 11.C. Changes in U.S. coal consumption
R2: Short tons
P3: 2014-24 avg. | Q3: Q1 | R3: -3668.8
Q4: Q2 | R4: -3573.3
Q5: Q3 | R5: -3813.2
Q6: Q4 | R6: -3632.8
P7: 2025 | Q7: Q1 | R7: 6091.1
Q8: Q2 | R8: 2809.5
Q9: Q3 | R9: 2315
Q10: Q4 | R10: 1425.5
A34: Sources: U.S. Energy Information Administration (EIA); World Bank.
A35: Note: avg. = average. Monthly data for U.S. coal consumption by the electric power sector. Data show year-on-year quarterly changes. Last observation is November 2025. 2025Q4 includes October and November.
A38: Return to Read Me

Sheet 11.D
A1: Figure 11.D. Changes in power generation by source in China and India
Q4: China | S4: India
O5: Chart | Q5: 2020-24 China | R5: 2025 China | S5: 2020-24 India (RHS) | T5: 2025 India (RHS)
P6: Solar and wind | Q6: 176 | R6: 270.5
P7: Hydro | Q7: 24.2 | R7: 40.1
P8: Thermal | Q8: 235.7 | R8: -49.2
P9: Nuclear | Q9: 19.3 | R9: 36.3
P10: Power output | Q10: 455.2 | R10: 297.8
P11: Thermal | S11: 63.1 | T11: -50.8
P12: Solar + Wind | S12: 21.2 | T12: 53.2
P13: Hydro | S13: -0.9 | T13: 22.3
P14: Nuclear | S14: 1.9 | T14: -0.9
P15: Power output | S15: 85.3 | T15: 23.9
A34: Sources: National Bureau of Statistics of China; National Institution for Transforming India; World Bank.
A35: Note: RHS = right-hand scale; TWh = terawatt hour. Composition of China’s and India’s power output changes by source. “Thermal” includes oil, natural gas, and coal. Data show 2025 data and the average between 2020–24. “Hydro” includes hydro, small-hydro, and bio power for India.
A39: Return to Read Me
